<robot name="6dofrobot">

	<!-- * * * Link Definitions * * * -->
 	<link name="base_link">
		<visual>
		    <origin xyz="0 0 0.0375" rpy="0 0 0"/>
          <axis xyz="0 0 0" />
			<geometry>
				<cylinder radius="0.09" length="0.075"/>
			</geometry>
			<material name="color1">
	       		<color rgba="0.1 0.1 0.1 1.0"/>
	     	</material>
		</visual>	
	</link>

	<joint name="joint1" type="revolute">
       <parent link="base_link"/>
       <child link="arm1"/>
       <origin xyz="0 0 0.0" rpy="0 0 0" />
       <axis xyz="0 0 1" />
    </joint>

    <link name="arm1">
		<visual>
		    <origin xyz="0 0 0.0825" rpy="0 0 0"/>
          	<axis xyz="0 0 0" />
			<geometry>
				<box size="0.08 0.03 0.015"/>
			</geometry>
			<material name="color2">
	       		<color rgba="0.2 0.2 0.2 1.0"/>
	     	</material>
		</visual>	
	</link>

    <joint name="joint2" type="revolute">
       <parent link="arm1"/>
       <child link="arm2"/>
       <origin xyz="0 0 0.09" rpy="0 0 0" />
       <axis xyz="1 0 0" />
    </joint>

    <link name="arm2">
		<visual>
		    <origin xyz="0 0 0.04" rpy="0 0 0"/>
          	<axis xyz="0 0 0" />
			<geometry>
				<box size="0.08 0.03 0.08"/>
			</geometry>
			<material name="color1">
	       		<color rgba="0.1 0.1 0.1 1.0 1.0"/>
	     	</material>
		</visual>	
	</link>

	<joint name="joint3" type="revolute">
       <parent link="arm2"/>
       <child link="arm3"/>
       <origin xyz="0 0 0.08" rpy="0 0 0" />
       <axis xyz="1 0 0" />
    </joint>

    <link name="arm3">
		<visual>
		    <origin xyz="0 0 0.04" rpy="0 0 0"/>
          	<axis xyz="0 0 0" />
			<geometry>
				<box size="0.08 0.03 0.08"/>
			</geometry>
			<material name="color2">
	       		<color rgba="0.2 0.2 0.2 1.0"/>
	     	</material>
		</visual>	
	</link>

	<joint name="joint4" type="revolute">
       <parent link="arm3"/>
       <child link="arm4"/>
       <origin xyz="0 0 0.08" rpy="0 0 0" />
       <axis xyz="1 0 0" />
    </joint>

    <link name="arm4">
		<visual>
		    <origin xyz="0 0 0.04" rpy="0 0 0"/>
          	<axis xyz="0 0 0" />
			<geometry>
				<box size="0.08 0.03 0.08"/>
			</geometry>
			<material name="color1">
	       		<color rgba="0.1 0.1 0.1 1.0 1.0"/>
	     	</material>
		</visual>	
	</link>

	<joint name="joint5" type="revolute">
       <parent link="arm4"/>
       <child link="arm5"/>
       <origin xyz="0 0 0.08" rpy="0 0 0" />
       <axis xyz="0 0 1" />
    </joint>

    <link name="arm5">
		<visual>
		    <origin xyz="0 0 0.06" rpy="0 0 0"/>
          	<axis xyz="0 0 0" />
			<geometry>
				<box size="0.04 0.02 0.12"/>
			</geometry>
			<material name="color2">
	       		<color rgba="0.2 0.2 0.2 1.0"/>
	     	</material>
		</visual>	
	</link>


</robot>